<robot
  name="thormang_mobile">
  <link
    name="base_link">
    <inertial>
      <origin
        xyz="-0.0602179305439518 2.22044604925031E-16 -0.83137322890434"
        rpy="0 0 0" />
      <mass
        value="43.0172800829917" />
      <inertia
        ixx="2.67241854525916"
        ixy="6.09203297164631E-18"
        ixz="0.174521019181904"
        iyy="2.87153281637056"
        iyz="-2.68823711085977E-16"
        izz="1.34826419418939" />
    </inertial>
    <visual>
      <origin
        xyz="0 0 0"
        rpy="0 0 0" />
      <geometry>
        <mesh
          filename="package://thormang_mobile_description/meshes/base_link.STL" />
      </geometry>
      <material
        name="">
        <color
          rgba="0.792156862745098 0.819607843137255 0.933333333333333 1" />
      </material>
    </visual>
    <collision>
      <origin
        xyz="0 0 0"
        rpy="0 0 0" />
      <geometry>
        <mesh
          filename="package://thormang_mobile_description/meshes/base_link.STL" />
      </geometry>
    </collision>
  </link>
  <link
    name="right_wheel">
    <inertial>
      <origin
        xyz="0 0 0.00106593770977037"
        rpy="0 0 0" />
      <mass
        value="2.52491529444972" />
      <inertia
        ixx="0.00823770242625175"
        ixy="-1.61540557706546E-34"
        ixz="2.67909598937724E-20"
        iyy="0.00823770242625175"
        iyz="1.19667226848005E-18"
        izz="0.0139879933696645" />
    </inertial>
    <visual>
      <origin
        xyz="0 0 0"
        rpy="0 0 0" />
      <geometry>
        <mesh
          filename="package://thormang_mobile_description/meshes/right_wheel.STL" />
      </geometry>
      <material
        name="">
        <color
          rgba="0.792156862745098 0.819607843137255 0.933333333333333 1" />
      </material>
    </visual>
    <collision>
      <origin
        xyz="0 0 0"
        rpy="0 0 0" />
      <geometry>
        <mesh
          filename="package://thormang_mobile_description/meshes/right_wheel.STL" />
      </geometry>
    </collision>
  </link>
  <joint
    name="right_wheel_joint"
    type="continuous">
    <origin
      xyz="0 -0.1995 -1.013025"
      rpy="1.5707963267949 0 0" />
    <parent
      link="base_link" />
    <child
      link="right_wheel" />
    <axis
      xyz="0 0 1" />
  </joint>
  <link
    name="left_wheel">
    <inertial>
      <origin
        xyz="-3.46944695195361E-18 0 0.00158320057450867"
        rpy="0 0 0" />
      <mass
        value="2.47386441382888" />
      <inertia
        ixx="0.00817359016529869"
        ixy="-2.28038141391017E-35"
        ixz="5.64752797459557E-20"
        iyy="0.00817359016529869"
        iyz="-2.38125120558804E-35"
        izz="0.0139260941769117" />
    </inertial>
    <visual>
      <origin
        xyz="0 0 0"
        rpy="0 0 0" />
      <geometry>
        <mesh
          filename="package://thormang_mobile_description/meshes/left_wheel.STL" />
      </geometry>
      <material
        name="">
        <color
          rgba="0.792156862745098 0.819607843137255 0.933333333333333 1" />
      </material>
    </visual>
    <collision>
      <origin
        xyz="0 0 0"
        rpy="0 0 0" />
      <geometry>
        <mesh
          filename="package://thormang_mobile_description/meshes/left_wheel.STL" />
      </geometry>
    </collision>
  </link>
  <joint
    name="left_wheel_joint"
    type="continuous">
    <origin
      xyz="0 0.1995 -1.013025"
      rpy="1.5707963267949 0 3.14159265358979" />
    <parent
      link="base_link" />
    <child
      link="left_wheel" />
    <axis
      xyz="0 0 1" />
  </joint>
  <link
    name="right_1">
    <inertial>
      <origin
        xyz="-1.19381734765139E-06 1.11022302462516E-16 5.72399936373813E-05"
        rpy="0 0 0" />
      <mass
        value="0.388328877054962" />
      <inertia
        ixx="0.000204963127082801"
        ixy="-3.46116525746152E-20"
        ixz="9.87790329083044E-09"
        iyy="0.000763413335974693"
        iyz="-7.54254355082987E-20"
        izz="0.000763898249170679" />
    </inertial>
    <visual>
      <origin
        xyz="0 0 0"
        rpy="0 0 0" />
      <geometry>
        <mesh
          filename="package://thormang_mobile_description/meshes/right_1.STL" />
      </geometry>
      <material
        name="">
        <color
          rgba="0.792156862745098 0.819607843137255 0.933333333333333 1" />
      </material>
    </visual>
    <collision>
      <origin
        xyz="0 0 0"
        rpy="0 0 0" />
      <geometry>
        <mesh
          filename="package://thormang_mobile_description/meshes/right_1.STL" />
      </geometry>
    </collision>
  </link>
  <joint
    name="right_joint1"
    type="revolute">
    <origin
      xyz="0 -0.228 0"
      rpy="1.5707963267949 0 0" />
    <parent
      link="base_link" />
    <child
      link="right_1" />
    <axis
      xyz="0 0 1" />
<limit
      lower="-3.1416"
      upper="3.1416"
      effort="0"
      velocity="0" />
  </joint>
  <link
    name="right_2">
    <inertial>
      <origin
        xyz="5.55111512312578E-17 -0.0390273943930688 1.11022302462516E-16"
        rpy="0 0 0" />
      <mass
        value="0.0993494348351601" />
      <inertia
        ixx="0.000262823545404629"
        ixy="5.77509746109188E-20"
        ixz="6.77514831241087E-20"
        iyy="0.000265542690959206"
        iyz="1.97803131193416E-19"
        izz="4.93574177718396E-05" />
    </inertial>
    <visual>
      <origin
        xyz="0 0 0"
        rpy="0 0 0" />
      <geometry>
        <mesh
          filename="package://thormang_mobile_description/meshes/right_2.STL" />
      </geometry>
      <material
        name="">
        <color
          rgba="0.792156862745098 0.819607843137255 0.933333333333333 1" />
      </material>
    </visual>
    <collision>
      <origin
        xyz="0 0 0"
        rpy="0 0 0" />
      <geometry>
        <mesh
          filename="package://thormang_mobile_description/meshes/right_2.STL" />
      </geometry>
    </collision>
  </link>
  <joint
    name="right_joint2"
    type="revolute">
    <origin
      xyz="0 0 0"
      rpy="-1.5707963267949 0 -1.5707963267949" />
    <parent
      link="right_1" />
    <child
      link="right_2" />
    <axis
      xyz="0 0 1" />
   <limit
      lower="-1.5708"
      upper="1.5708"
      effort="0"
      velocity="0" />
  </joint>
  <link
    name="right_3">
    <inertial>
      <origin
        xyz="-3.46944695195361E-18 -0.00633885667643569 0.134288270498482"
        rpy="0 0 0" />
      <mass
        value="1.25823640903853" />
      <inertia
        ixx="0.00655450650492442"
        ixy="-9.95447879554814E-20"
        ixz="5.84588145733796E-19"
        iyy="0.00692588909593473"
        iyz="-0.000656807450164779"
        izz="0.00139584846465015" />
    </inertial>
    <visual>
      <origin
        xyz="0 0 0"
        rpy="0 0 0" />
      <geometry>
        <mesh
          filename="package://thormang_mobile_description/meshes/right_3.STL" />
      </geometry>
      <material
        name="">
        <color
          rgba="0.792156862745098 0.819607843137255 0.933333333333333 1" />
      </material>
    </visual>
    <collision>
      <origin
        xyz="0 0 0"
        rpy="0 0 0" />
      <geometry>
        <mesh
          filename="package://thormang_mobile_description/meshes/right_3.STL" />
      </geometry>
    </collision>
  </link>
  <joint
    name="right_joint3"
    type="revolute">
    <origin
      xyz="0 -0.0449999999999999 0"
      rpy="1.5707963267949 -1.5707963267949 0" />
    <parent
      link="right_2" />
    <child
      link="right_3" />
    <axis
      xyz="0 0 1" />
 <limit
      lower="-3.1416"
      upper="3.1416"
      effort="0"
      velocity="0" />
  </joint>
  <link
    name="right_4">
    <inertial>
      <origin
        xyz="-0.110538726850988 -0.0682697078550791 1.38777878078145E-17"
        rpy="0 0 0" />
      <mass
        value="0.8542020729765" />
      <inertia
        ixx="0.00187314778864782"
        ixy="0.00106762468415396"
        ixz="1.13260079080541E-20"
        iyy="0.00190948729380631"
        iyz="-2.67447542688319E-19"
        izz="0.00263725850837556" />
    </inertial>
    <visual>
      <origin
        xyz="0 0 0"
        rpy="0 0 0" />
      <geometry>
        <mesh
          filename="package://thormang_mobile_description/meshes/right_4.STL" />
      </geometry>
      <material
        name="">
        <color
          rgba="0.792156862745098 0.819607843137255 0.933333333333333 1" />
      </material>
    </visual>
    <collision>
      <origin
        xyz="0 0 0"
        rpy="0 0 0" />
      <geometry>
        <mesh
          filename="package://thormang_mobile_description/meshes/right_4.STL" />
      </geometry>
    </collision>
  </link>
  <joint
    name="right_joint4"
    type="revolute">
    <origin
      xyz="0 -0.0260466649870931 0.215100258115898"
      rpy="0 1.5707963267949 0" />
    <parent
      link="right_3" />
    <child
      link="right_4" />
    <axis
      xyz="0 0 1" />
 <limit
      lower="-1.5708"
      upper="2.3562"
      effort="0"
      velocity="0" />
  </joint>
  <link
    name="right_5">
    <inertial>
      <origin
        xyz="-3.46944695195361E-18 2.22044604925031E-16 0.0252560468069318"
        rpy="0 0 0" />
      <mass
        value="0.299936477023501" />
      <inertia
        ixx="0.000166924011443148"
        ixy="1.32154227611693E-20"
        ixz="7.29661557768319E-21"
        iyy="0.000286844799919657"
        iyz="2.71050543121376E-20"
        izz="0.000278628812587253" />
    </inertial>
    <visual>
      <origin
        xyz="0 0 0"
        rpy="0 0 0" />
      <geometry>
        <mesh
          filename="package://thormang_mobile_description/meshes/right_5.STL" />
      </geometry>
      <material
        name="">
        <color
          rgba="0.792156862745098 0.819607843137255 0.933333333333333 1" />
      </material>
    </visual>
    <collision>
      <origin
        xyz="0 0 0"
        rpy="0 0 0" />
      <geometry>
        <mesh
          filename="package://thormang_mobile_description/meshes/right_5.STL" />
      </geometry>
    </collision>
  </link>
  <joint
    name="right_joint5"
    type="revolute">
    <origin
      xyz="-0.176073181644258 -0.13364318164426 0"
      rpy="0.7854 -1.5707963267949 0" />
    <parent
      link="right_4" />
    <child
      link="right_5" />
    <axis
      xyz="0 0 1" />
 <limit
      lower="-3.1416"
      upper="3.1416"
      effort="0"
      velocity="0" />
  </joint>
  <link
    name="right_6">
    <inertial>
      <origin
        xyz="0 -0.0401576886925545 6.93889390390723E-18"
        rpy="0 0 0" />
      <mass
        value="0.0289659939861001" />
      <inertia
        ixx="5.57348377322709E-05"
        ixy="-1.01643953670516E-20"
        ixz="-1.46415091925883E-20"
        iyy="4.89879341308427E-05"
        iyz="-4.21446995874658E-20"
        izz="1.86920389432603E-05" />
    </inertial>
    <visual>
      <origin
        xyz="0 0 0"
        rpy="0 0 0" />
      <geometry>
        <mesh
          filename="package://thormang_mobile_description/meshes/right_6.STL" />
      </geometry>
      <material
        name="">
        <color
          rgba="0.792156862745098 0.819607843137255 0.933333333333333 1" />
      </material>
    </visual>
    <collision>
      <origin
        xyz="0 0 0"
        rpy="0 0 0" />
      <geometry>
        <mesh
          filename="package://thormang_mobile_description/meshes/right_6.STL" />
      </geometry>
    </collision>
  </link>
  <joint
    name="right_joint6"
    type="revolute">
    <origin
      xyz="0.000149999999999435 0 0.0269999999999972"
      rpy="-1.5707963267949 0 -1.5707963267949" />
    <parent
      link="right_5" />
    <child
      link="right_6" />
    <axis
      xyz="0 0 1" />
<limit
      lower="-1.5708"
      upper="1.5708"
      effort="0"
      velocity="0" />
  </joint>
  <link
    name="right_7">
    <inertial>
      <origin
        xyz="6.93889390390723E-18 0.00252707668655416 -0.180031051043445"
        rpy="0 0 0" />
      <mass
        value="0.428873545699055" />
      <inertia
        ixx="0.00381383556642902"
        ixy="3.55341126936981E-20"
        ixz="9.02012829737498E-20"
        iyy="0.00381211467778268"
        iyz="0.000157395840922103"
        izz="0.000127668695985748" />
    </inertial>
    <visual>
      <origin
        xyz="0 0 0"
        rpy="0 0 0" />
      <geometry>
        <mesh
          filename="package://thormang_mobile_description/meshes/right_7.STL" />
      </geometry>
      <material
        name="">
        <color
          rgba="0.792156862745098 0.819607843137255 0.933333333333333 1" />
      </material>
    </visual>
    <collision>
      <origin
        xyz="0 0 0"
        rpy="0 0 0" />
      <geometry>
        <mesh
          filename="package://thormang_mobile_description/meshes/right_7.STL" />
      </geometry>
    </collision>
  </link>
  <joint
    name="right_joint7"
    type="revolute">
    <origin
      xyz="0 -0.372763647260397 0"
      rpy="1.5707963267949 -1.5707963267949 0" />
    <parent
      link="right_6" />
    <child
      link="right_7" />
    <axis
      xyz="0 0 1" />
  <limit
      lower="-3.1416"
      upper="3.1416"
      effort="0"
      velocity="0" />
  </joint>
  <link
    name="right_finger">
    <inertial>
      <origin
        xyz="0.0048588099124478 -0.0962457554270082 3.46944695195361E-18"
        rpy="0 0 0" />
      <mass
        value="0.0743348693421164" />
      <inertia
        ixx="0.00012235189614095"
        ixy="-6.97589954062847E-06"
        ixz="7.09743258142642E-24"
        iyy="1.2066703300348E-05"
        iyz="-5.44937215756073E-21"
        izz="0.000115752232168572" />
    </inertial>
    <visual>
      <origin
        xyz="0 0 0"
        rpy="0 0 0" />
      <geometry>
        <mesh
          filename="package://thormang_mobile_description/meshes/right_finger.STL" />
      </geometry>
      <material
        name="">
        <color
          rgba="0.792156862745098 0.819607843137255 0.933333333333333 1" />
      </material>
    </visual>
    <collision>
      <origin
        xyz="0 0 0"
        rpy="0 0 0" />
      <geometry>
        <mesh
          filename="package://thormang_mobile_description/meshes/right_finger.STL" />
      </geometry>
    </collision>
  </link>
  <joint
    name="right_finger_j"
    type="revolute">
    <origin
      xyz="0 -0.0170000000000023 -0.115559999999997"
      rpy="-1.5707963267949 -1.16308741352901 1.5707963267949" />
    <parent
      link="right_7" />
    <child
      link="right_finger" />
    <axis
      xyz="0 0 1" />
  <limit
      lower="0"
      upper="1.1631"
      effort="0"
      velocity="0" />
  </joint>
  <link name="right_finger_dummy">
  </link>
  <joint name="right_finger_dummy_j" type="fixed">
  <origin
    xyz="-0.025 0 -0.055"
    rpy="0 0 0"/>
  <parent 
   link="right_7"/>
  <child
   link="right_finger_dummy" />
  </joint>
  <link
    name="left_1">
    <inertial>
      <origin
        xyz="-1.19381734764792E-06 1.66533453693773E-16 5.72399936374923E-05"
        rpy="0 0 0" />
      <mass
        value="0.388328877054961" />
      <inertia
        ixx="0.0002049631270828"
        ixy="-4.14646099273951E-20"
        ixz="9.87790329078828E-09"
        iyy="0.000763413335974691"
        iyz="-9.86953850615174E-20"
        izz="0.000763898249170678" />
    </inertial>
    <visual>
      <origin
        xyz="0 0 0"
        rpy="0 0 0" />
      <geometry>
        <mesh
          filename="package://thormang_mobile_description/meshes/left_1.STL" />
      </geometry>
      <material
        name="">
        <color
          rgba="0.792156862745098 0.819607843137255 0.933333333333333 1" />
      </material>
    </visual>
    <collision>
      <origin
        xyz="0 0 0"
        rpy="0 0 0" />
      <geometry>
        <mesh
          filename="package://thormang_mobile_description/meshes/left_1.STL" />
      </geometry>
    </collision>
  </link>
  <joint
    name="left_joint1"
    type="revolute">
    <origin
      xyz="0 0.228 0"
      rpy="1.5707963267949 0 -3.14159265358979" />
    <parent
      link="base_link" />
    <child
      link="left_1" />
    <axis
      xyz="0 0 1" />
<limit
      lower="-3.1416"
      upper="3.1416"
      effort="0"
      velocity="0" />
  </joint>
  <link
    name="left_2">
    <inertial>
      <origin
        xyz="0 -0.0390273943930691 1.00613961606655E-16"
        rpy="0 0 0" />
      <mass
        value="0.0993494348351601" />
      <inertia
        ixx="0.00026282354540463"
        ixy="2.82709921957486E-20"
        ixz="-2.58070599206176E-20"
        iyy="0.000265542690959207"
        iyz="2.4871677961662E-19"
        izz="4.93574177718397E-05" />
    </inertial>
    <visual>
      <origin
        xyz="0 0 0"
        rpy="0 0 0" />
      <geometry>
        <mesh
          filename="package://thormang_mobile_description/meshes/left_2.STL" />
      </geometry>
      <material
        name="">
        <color
          rgba="0.792156862745098 0.819607843137255 0.933333333333333 1" />
      </material>
    </visual>
    <collision>
      <origin
        xyz="0 0 0"
        rpy="0 0 0" />
      <geometry>
        <mesh
          filename="package://thormang_mobile_description/meshes/left_2.STL" />
      </geometry>
    </collision>
  </link>
  <joint
    name="left_joint2"
    type="revolute">
    <origin
      xyz="0 0 0"
      rpy="-1.5707963267949 0 1.5707963267949" />
    <parent
      link="left_1" />
    <child
      link="left_2" />
    <axis
      xyz="0 0 1" />
  <limit
      lower="-1.5708"
      upper="1.5708"
      effort="0"
      velocity="0" />
  </joint>
  <link
    name="left_3">
    <inertial>
      <origin
        xyz="6.93889390390723E-18 -0.00633885667643574 0.134288270498482"
        rpy="0 0 0" />
      <mass
        value="1.25823640903854" />
      <inertia
        ixx="0.00655450650492442"
        ixy="-2.08083494221391E-19"
        ixz="1.09609937296697E-18"
        iyy="0.00692588909593473"
        iyz="-0.000656807450164781"
        izz="0.00139584846465016" />
    </inertial>
    <visual>
      <origin
        xyz="0 0 0"
        rpy="0 0 0" />
      <geometry>
        <mesh
          filename="package://thormang_mobile_description/meshes/left_3.STL" />
      </geometry>
      <material
        name="">
        <color
          rgba="0.792156862745098 0.819607843137255 0.933333333333333 1" />
      </material>
    </visual>
    <collision>
      <origin
        xyz="0 0 0"
        rpy="0 0 0" />
      <geometry>
        <mesh
          filename="package://thormang_mobile_description/meshes/left_3.STL" />
      </geometry>
    </collision>
  </link>
  <joint
    name="left_joint3"
    type="revolute">
    <origin
      xyz="0 -0.0449999999999999 0"
      rpy="1.5707963267949 1.5707963267949 0" />
    <parent
      link="left_2" />
    <child
      link="left_3" />
    <axis
      xyz="0 0 1" />
 <limit
      lower="-3.1416"
      upper="3.1416"
      effort="0"
      velocity="0" />
  </joint>
  <link
    name="left_4">
    <inertial>
      <origin
        xyz="0.110538726850988 -0.0682697078550791 1.38777878078145E-17"
        rpy="0 0 0" />
      <mass
        value="0.854202072976499" />
      <inertia
        ixx="0.00187314778864782"
        ixy="-0.00106762468415396"
        ixz="1.04580355858111E-19"
        iyy="0.00190948729380631"
        iyz="2.12902324753741E-19"
        izz="0.00263725850837556" />
    </inertial>
    <visual>
      <origin
        xyz="0 0 0"
        rpy="0 0 0" />
      <geometry>
        <mesh
          filename="package://thormang_mobile_description/meshes/left_4.STL" />
      </geometry>
      <material
        name="">
        <color
          rgba="0.792156862745098 0.819607843137255 0.933333333333333 1" />
      </material>
    </visual>
    <collision>
      <origin
        xyz="0 0 0"
        rpy="0 0 0" />
      <geometry>
        <mesh
          filename="package://thormang_mobile_description/meshes/left_4.STL" />
      </geometry>
    </collision>
  </link>
  <joint
    name="left_joint4"
    type="revolute">
    <origin
      xyz="0 -0.0260466649870893 0.215100258115897"
      rpy="0 -1.5707963267949 0" />
    <parent
      link="left_3" />
    <child
      link="left_4" />
    <axis
      xyz="0 0 1" />
 <limit
      lower="-2.3562"
      upper="1.5708"
      effort="0"
      velocity="0" />
  </joint>
  <link
    name="left_5">
    <inertial>
      <origin
        xyz="3.46944695195361E-18 0 0.0252560468069321"
        rpy="0 0 0" />
      <mass
        value="0.2999364770235" />
      <inertia
        ixx="0.000166924011443148"
        ixy="-5.11753046965996E-20"
        ixz="-2.29148484211491E-20"
        iyy="0.000286844799919656"
        iyz="1.35525271560688E-20"
        izz="0.000278628812587252" />
    </inertial>
    <visual>
      <origin
        xyz="0 0 0"
        rpy="0 0 0" />
      <geometry>
        <mesh
          filename="package://thormang_mobile_description/meshes/left_5.STL" />
      </geometry>
      <material
        name="">
        <color
          rgba="0.792156862745098 0.819607843137255 0.933333333333333 1" />
      </material>
    </visual>
    <collision>
      <origin
        xyz="0 0 0"
        rpy="0 0 0" />
      <geometry>
        <mesh
          filename="package://thormang_mobile_description/meshes/left_5.STL" />
      </geometry>
    </collision>
  </link>
  <joint
    name="left_joint5"
    type="revolute">
    <origin
      xyz="0.176073181644258 -0.133643181644257 0"
      rpy="0.785398163397447 1.5707963267949 0" />
    <parent
      link="left_4" />
    <child
      link="left_5" />
    <axis
      xyz="0 0 -1" />
 <limit
      lower="-3.1416"
      upper="3.1416"
      effort="0"
      velocity="0" />
  </joint>
  <link
    name="left_6">
    <inertial>
      <origin
        xyz="1.38777878078145E-16 -0.0401576886925543 1.17961196366423E-16"
        rpy="0 0 0" />
      <mass
        value="0.0289659939861006" />
      <inertia
        ixx="5.57348377322715E-05"
        ixy="1.18584612615602E-20"
        ixz="-3.63429455432985E-20"
        iyy="4.89879341308432E-05"
        iyz="-6.6040658867873E-20"
        izz="1.86920389432606E-05" />
    </inertial>
    <visual>
      <origin
        xyz="0 0 0"
        rpy="0 0 0" />
      <geometry>
        <mesh
          filename="package://thormang_mobile_description/meshes/left_6.STL" />
      </geometry>
      <material
        name="">
        <color
          rgba="0.792156862745098 0.819607843137255 0.933333333333333 1" />
      </material>
    </visual>
    <collision>
      <origin
        xyz="0 0 0"
        rpy="0 0 0" />
      <geometry>
        <mesh
          filename="package://thormang_mobile_description/meshes/left_6.STL" />
      </geometry>
    </collision>
  </link>
  <joint
    name="left_joint6"
    type="revolute">
    <origin
      xyz="-0.000150000000000306 0 0.0270000000000001"
      rpy="-1.5707963267949 5.55111512312578E-16 1.5707963267949" />
    <parent
      link="left_5" />
    <child
      link="left_6" />
    <axis
      xyz="0 0 1" />
  <limit
      lower="-1.5708"
      upper="1.5708"
      effort="0"
      velocity="0" />
  </joint>
  <link
    name="left_7">
    <inertial>
      <origin
        xyz="-0.0025270766865544 6.93889390390723E-18 -0.180031051043445"
        rpy="0 0 0" />
      <mass
        value="0.428873545699056" />
      <inertia
        ixx="0.00381211467778271"
        ixy="5.39797105551682E-20"
        ixz="-0.000157395840922104"
        iyy="0.00381383556642905"
        iyz="-3.20601518542159E-19"
        izz="0.000127668695985749" />
    </inertial>
    <visual>
      <origin
        xyz="0 0 0"
        rpy="0 0 0" />
      <geometry>
        <mesh
          filename="package://thormang_mobile_description/meshes/left_7.STL" />
      </geometry>
      <material
        name="">
        <color
          rgba="0.792156862745098 0.819607843137255 0.933333333333333 1" />
      </material>
    </visual>
    <collision>
      <origin
        xyz="0 0 0"
        rpy="0 0 0" />
      <geometry>
        <mesh
          filename="package://thormang_mobile_description/meshes/left_7.STL" />
      </geometry>
    </collision>
  </link>
  <joint
    name="left_joint7"
    type="revolute">
    <origin
      xyz="0 -0.372763647260397 0"
      rpy="-1.5707963267949 -1.19729462427353E-16 -3.14159265358979" />
    <parent
      link="left_6" />
    <child
      link="left_7" />
    <axis
      xyz="0 0 1" />
  <limit
      lower="-3.1416"
      upper="3.1416"
      effort="0"
      velocity="0" />
  </joint>
  <link
    name="left_finger">
    <inertial>
      <origin
        xyz="0.00485880991244797 -0.0962457554270083 -3.46944695195361E-18"
        rpy="0 0 0" />
      <mass
        value="0.0743348693421169" />
      <inertia
        ixx="0.00012235189614095"
        ixy="-6.97589954062859E-06"
        ixz="2.28194500474435E-21"
        iyy="1.20667033003482E-05"
        iyz="-1.00222700933464E-20"
        izz="0.000115752232168572" />
    </inertial>
    <visual>
      <origin
        xyz="0 0 0"
        rpy="0 0 0" />
      <geometry>
        <mesh
          filename="package://thormang_mobile_description/meshes/left_finger.STL" />
      </geometry>
      <material
        name="">
        <color
          rgba="0.792156862745098 0.819607843137255 0.933333333333333 1" />
      </material>
    </visual>
    <collision>
      <origin
        xyz="0 0 0"
        rpy="0 0 0" />
      <geometry>
        <mesh
          filename="package://thormang_mobile_description/meshes/left_finger.STL" />
      </geometry>
    </collision>
  </link>
  <joint
    name="left_finger_j"
    type="revolute">
    <origin
      xyz="0.017 0 -0.11556"
      rpy="-1.5707963267949 -1.16308741352901 3.14159265358979" />
    <parent
      link="left_7" />
    <child
      link="left_finger" />
    <axis
      xyz="0 0 1" />
 <limit
      lower="0"
      upper="1.1631"
      effort="0"
      velocity="0" />
  </joint>
  <link name="left_finger_dummy">
  </link>
  <joint name="left_finger_dummy_j" type="fixed">
  <origin
    xyz="-0.025 0 -0.055"
    rpy="0 0 0"/>
  <parent 
   link="left_7"/>
  <child
   link="left_finger_dummy" />
  </joint>
  <link
    name="neck_lidar">
    <inertial>
      <origin
        xyz="0 0 0"
        rpy="0 0 0" />
      <mass
        value="0.600886219667429" />
      <inertia
        ixx="0.000376915309144553"
        ixy="5.77473857832102E-20"
        ixz="7.1866206177619E-20"
        iyy="0.00148043530914456"
        iyz="-1.79005206087208E-20"
        izz="0.00146464292492815" />
    </inertial>
    <visual>
      <origin
        xyz="0 0 0"
        rpy="0 0 0" />

      <geometry>
        <box size="0.062 0.062 0.087"/>
      </geometry>
      <material
        name="">
        <color
          rgba="0.792156862745098 0.819607843137255 0.933333333333333 1" />
      </material>
    </visual>
    <collision>
      <origin
        xyz="0 0 0"
        rpy="0 0 0" />
	<geometry>
	  <box size="0.062 0.062 0.087"/>
	</geometry>
    </collision>
  </link>
  <joint
    name="neck_lidar_joint"
    type="revolute">
    <origin
      xyz="0.096 0 0.06"
      rpy="0 0 0" />
    <parent
      link="base_link" />
    <child
      link="neck_lidar" />
    <axis
      xyz="1 0 0" />
 <limit
      lower="-2.3562"
      upper="2.3562"
      effort="0"
      velocity="0" />
  </joint>
  <link
    name="head_link1">
    <inertial>
      <origin
        xyz="3.46944695195361E-18 0.0980273880233316 0"
        rpy="0 0 0" />
      <mass
        value="0.289459588438889" />
      <inertia
        ixx="0.000452539257668448"
        ixy="3.74076008637062E-20"
        ixz="1.45753380083627E-20"
        iyy="0.000286854602876727"
        iyz="-3.62173721177865E-20"
        izz="0.000250495868604429" />
    </inertial>
    <visual>
      <origin
        xyz="0 0 0"
        rpy="0 0 0" />
      <geometry>
        <mesh
          filename="package://thormang_mobile_description/meshes/head_link1.STL" />
      </geometry>
      <material
        name="">
        <color
          rgba="0.792156862745098 0.819607843137255 0.933333333333333 1" />
      </material>
    </visual>
    <collision>
      <origin
        xyz="0 0 0"
        rpy="0 0 0" />
      <geometry>
        <mesh
          filename="package://thormang_mobile_description/meshes/head_link1.STL" />
      </geometry>
    </collision>
  </link>
  <joint
    name="head_joint1"
    type="revolute">
    <origin
      xyz="0 0 0.0649999999999999"
      rpy="1.5707963267949 0 0" />
    <parent
      link="base_link" />
    <child
      link="head_link1" />
    <axis
      xyz="0 0 1" />
    <limit
      lower="-1.5708"
      upper="1.5708"
      effort="0"
      velocity="0" />
  </joint>
  <link
    name="head_link2">
    <inertial>
      <origin
        xyz="-2.22044604925031E-16 -1.04083408558608E-17 0.0362762296451919"
        rpy="0 0 0" />
      <mass
        value="0.153851261478765" />
      <inertia
        ixx="0.000122163497508344"
        ixy="-3.85566578664514E-22"
        ixz="3.11488563575842E-21"
        iyy="0.000122163497508344"
        iyz="3.47176548613171E-21"
        izz="4.62919448030282E-05" />
    </inertial>
    <visual>
      <origin
        xyz="0 0 0"
        rpy="0 0 0" />
      <geometry>
        <mesh
          filename="package://thormang_mobile_description/meshes/head_link2.STL" />
      </geometry>
      <material
        name="">
        <color
          rgba="0.792156862745098 0.819607843137255 0.933333333333333 1" />
      </material>
    </visual>
    <collision>
      <origin
        xyz="0 0 0"
        rpy="0 0 0" />
      <geometry>
        <mesh
          filename="package://thormang_mobile_description/meshes/head_link2.STL" />
      </geometry>
    </collision>
  </link>
  <joint
    name="head_joint2"
    type="revolute">
    <origin
      xyz="0 0.145 0"
      rpy="-1.5707963267949 1.5707963267949 0" />
    <parent
      link="head_link1" />
    <child
      link="head_link2" />
    <axis
      xyz="0 0 1" />
 <limit
      lower="-3.1416"
      upper="3.1416"
      effort="0"
      velocity="0" />
  </joint>
</robot>
