<robot
  name="thormang_mobile">
  <link
    name="base_link">
    <inertial>
      <origin
        xyz="-0.0602179305439518 2.22044604925031E-16 -0.83137322890434"
        rpy="0 0 0" />
      <mass
        value="43.0172800829917" />
      <inertia
        ixx="2.67241854525916"
        ixy="6.09203297164631E-18"
        ixz="0.174521019181904"
        iyy="2.87153281637056"
        iyz="-2.68823711085977E-16"
        izz="1.34826419418939" />
    </inertial>
    <visual>
      <origin
        xyz="0 0 0"
        rpy="0 0 0" />
      <geometry>
        <mesh
          filename="package://thormang_mobile_description/meshes/base_link.STL" />
      </geometry>
      <material
        name="">
        <color
          rgba="0.792156862745098 0.819607843137255 0.933333333333333 1" />
      </material>
    </visual>
    <collision>
      <origin
        xyz="0 0 0"
        rpy="0 0 0" />
      <geometry>
        <mesh
          filename="package://thormang_mobile_description/meshes/base_link.STL" />
      </geometry>
    </collision>
  </link>
  <link
    name="right_wheel">
    <inertial>
      <origin
        xyz="0 0 0.00106593770977037"
        rpy="0 0 0" />
      <mass
        value="2.52491529444972" />
      <inertia
        ixx="0.00823770242625175"
        ixy="-1.61540557706546E-34"
        ixz="2.67909598937724E-20"
        iyy="0.00823770242625175"
        iyz="1.19667226848005E-18"
        izz="0.0139879933696645" />
    </inertial>
    <visual>
      <origin
        xyz="0 0 0"
        rpy="0 0 0" />
      <geometry>
        <mesh
          filename="package://thormang_mobile_description/meshes/right_wheel.STL" />
      </geometry>
      <material
        name="">
        <color
          rgba="0.792156862745098 0.819607843137255 0.933333333333333 1" />
      </material>
    </visual>
    <collision>
      <origin
        xyz="0 0 0"
        rpy="0 0 0" />
      <geometry>
        <mesh
          filename="package://thormang_mobile_description/meshes/right_wheel.STL" />
      </geometry>
    </collision>
  </link>
  <joint
    name="right_wheel_joint"
    type="continuous">
    <origin
      xyz="0 -0.1995 -1.013025"
      rpy="1.5707963267949 0 0" />
    <parent
      link="base_link" />
    <child
      link="right_wheel" />
    <axis
      xyz="0 0 1" />
  </joint>
  <link
    name="left_wheel">
    <inertial>
      <origin
        xyz="-3.46944695195361E-18 0 0.00158320057450867"
        rpy="0 0 0" />
      <mass
        value="2.47386441382888" />
      <inertia
        ixx="0.00817359016529869"
        ixy="-2.28038141391017E-35"
        ixz="5.64752797459557E-20"
        iyy="0.00817359016529869"
        iyz="-2.38125120558804E-35"
        izz="0.0139260941769117" />
    </inertial>
    <visual>
      <origin
        xyz="0 0 0"
        rpy="0 0 0" />
      <geometry>
        <mesh
          filename="package://thormang_mobile_description/meshes/left_wheel.STL" />
      </geometry>
      <material
        name="">
        <color
          rgba="0.792156862745098 0.819607843137255 0.933333333333333 1" />
      </material>
    </visual>
    <collision>
      <origin
        xyz="0 0 0"
        rpy="0 0 0" />
      <geometry>
        <mesh
          filename="package://thormang_mobile_description/meshes/left_wheel.STL" />
      </geometry>
    </collision>
  </link>
  <joint
    name="left_wheel_joint"
    type="continuous">
    <origin
      xyz="0 0.1995 -1.013025"
      rpy="1.5707963267949 0 3.14159265358979" />
    <parent
      link="base_link" />
    <child
      link="left_wheel" />
    <axis
      xyz="0 0 1" />
  </joint>
  <link
    name="neck_lidar">
    <inertial>
      <origin
        xyz="0 0 -0.0135"
        rpy="0 0 0" />
      <mass
        value="0.600886219667429" />
      <inertia
        ixx="0.000376915309144553"
        ixy="5.77473857832102E-20"
        ixz="7.1866206177619E-20"
        iyy="0.00148043530914456"
        iyz="-1.79005206087208E-20"
        izz="0.00146464292492815" />
    </inertial>
    <visual>
      <origin
        xyz="0 0 -0.0135"
        rpy="0 0 0" />

      <geometry>
        <box size="0.062 0.062 0.087"/>
      </geometry>
      <material
        name="">
        <color
          rgba="0.792156862745098 0.819607843137255 0.933333333333333 1" />
      </material>
    </visual>
    <collision>
      <origin
        xyz="0 0 -0.0135"
        rpy="0 0 0" />
	<geometry>
	  <box size="0.062 0.062 0.087"/>
	</geometry>
    </collision>
  </link>
  <joint
    name="neck_lidar_joint"
    type="revolute">
    <origin
      xyz="0.111 0 0.06"
      rpy="0 0 0" />
    <parent
      link="base_link" />
    <child
      link="neck_lidar" />
    <axis
      xyz="1 0 0" />
 <limit
      lower="-2.3562"
      upper="2.3562"
      effort="0"
      velocity="0" />
  </joint>
</robot>
